Workbook

Sheet 相关性复核
A1: ﻿query_id | B1: query_text | C1: language | D1: product_class | E1: query_type | F1: split | G1: candidate_scene_id | H1: record_id | I1: scene_start_time | J1: scene_end_time | K1: media_relative_path | L1: thumbnail_relative_path | M1: scene_text | N1: blind_order | O1: ai_relevance_grade | P1: ai_start_time | Q1: ai_end_time | R1: ai_evidence | S1: ai_evidence_sources | T1: ai_uncertainty | U1: ai_uncertainty_reason | V1: reviewer_id | W1: r1_relevance_grade | X1: r1_start_time | Y1: r1_end_time | Z1: r1_source_leakage | AA1: r1_evidence_notes | AB1: correction_reason | AC1: review_status | AD1: reviewed_at | AE1: grade_changed | AF1: time_changed | AG1: qc_status
A2: VQ-001 | B2: 空气炸锅怎样设置烹饪温度和时间？ | C2: zh-CN | D2: Air Fryer | E2: operation | F2: development | G2: airfryer-005-scene-0021 | H2: airfryer-005 | I2: 202.502 | J2: 207.465 | K2: items/airfryer-005-scene-0021/clip.mp4 | L2: items/airfryer-005-scene-0021/thumbnail.jpg | M2: ASR: air fryer, the basket goes and then we set the temperature VLM: Visual summary: A person is placing an air fryer basket containing food into an air fryer appliance on a white countertop. 视觉摘要: 一个人将装有食物的空气炸锅篮子放入空气炸锅中，置于白色台面上。 Visible product: Air Fryer Visible components: air fryer basket; air fryer appliance; white countertop; white cutting board; glass bowl; eggshells Visible actions: placing air fryer basket into air fryer appliance | N2: 1 | O2: 1 | R2: ASR mentions setting temperature after placing the basket, but no actual temperature or time setting is shown or spoken; VLM only shows placing the basket, not configuring settings. | S2: ASR|VLM | T2: low | U2: No visible or spoken evidence of temperature or time setting; only placement of basket is shown. | V2: R1 | W2: 1 | Z2: no | AA2: 画面显示将含食物的炸篮放入空气炸锅，未出现温度/时间旋钮或触控设置过程，ASR 仅提到'we set the temperature'但未给出具体数值或操作方法，无法回答如何设置。 | AC2: completed | AD2: 2026-07-27T22:01:34+08:00 | AE2: =IF(AC2<>"completed","",IF(W2=O2,"no","yes")) | AF2: =IF(AC2<>"completed","",IF(AND(X2=P2,Y2=Q2),"no","yes")) | AG2: =IF(AC2<>"completed","待复核",IF(OR(W2="",Z2="",AA2="",AD2=""),"缺少必填项",IF(AND(OR(AE2="yes",AF2="yes"),AB2=""),"修正原因缺失",IF(OR(W2=0,W2=1),IF(AND(X2="",Y2=""),"通过","0/1级时间应留空"),IF(AND(OR(W2=2,W2=3),X2<>"",Y2<>"",X2>=I2,Y2<=J2,Y2>X2),"通过","2/3级时间无效")))))
A3: VQ-001 | B3: 空气炸锅怎样设置烹饪温度和时间？ | C3: zh-CN | D3: Air Fryer | E3: operation | F3: development | G3: pressure-006-scene-0005 | H3: pressure-006 | I3: 15.083 | J3: 17.625 | K3: items/pressure-006-scene-0005/clip.mp4 | L3: items/pressure-006-scene-0005/thumbnail.jpg | M3: ASR: • Touch screen control, LCD display, visual window, cooking process at a glance VLM: Visual summary: A close-up of a yellow and black air fryer with a digital display and touch controls, showing food inside the basket. 视觉摘要: 一台黄黑相间的空气炸锅特写，配有数字显示屏和触控按钮，锅内可见食物。 Visible product: Air Fryer Visible components: digital display; touch controls; food inside basket; yellow and black casing | N3: 2 | O3: 1 | R3: The scene shows an air fryer with a digital display and touch controls, indicating it has a user interface for setting temperature and time, but no specific settings or actions are shown or described. | S3: VLM|ASR | T3: low | U3: No actual temperature or time setting is demonstrated or described in the evidence. | V3: R1 | W3: 1 | Z3: no | AA3: 画面展示空气炸锅触控/LCD面板与'880'显示，但未出现设置温度、时间的具体操作或数值，无法回答如何设置。 | AC3: completed | AD3: 2026-07-27T22:01:34+08:00 | AE3: =IF(AC3<>"completed","",IF(W3=O3,"no","yes")) | AF3: =IF(AC3<>"completed","",IF(AND(X3=P3,Y3=Q3),"no","yes")) | AG3: =IF(AC3<>"completed","待复核",IF(OR(W3="",Z3="",AA3="",AD3=""),"缺少必填项",IF(AND(OR(AE3="yes",AF3="yes"),AB3=""),"修正原因缺失",IF(OR(W3=0,W3=1),IF(AND(X3="",Y3=""),"通过","0/1级时间应留空"),IF(AND(OR(W3=2,W3=3),X3<>"",Y3<>"",X3>=I3,Y3<=J3,Y3>X3),"通过","2/3级时间无效")))))
A4: VQ-001 | B4: 空气炸锅怎样设置烹饪温度和时间？ | C4: zh-CN | D4: Air Fryer | E4: operation | F4: development | G4: airfryer-011-scene-0001 | H4: airfryer-011 | I4: 0.0 | J4: 107.95 | K4: items/airfryer-011-scene-0001/clip.mp4 | L4: items/airfryer-011-scene-0001/thumbnail.jpg | M4: ASR: Hi, welcome back to Montana, and today we're going to be making another one of my favorite air fryer recipes, grilled cheese. The ingredients are white bread, salted butter, sharp cheddar cheese, and Italian blend cheese. Your first step is to add some of your cheddar into the middle of your bread, and then sprinkle some Italian blend on top. Then butter the exterior of your bread. Put your grilled cheese inside of your air fryer, and then cook for four minutes. Now flip it over and then cook for another three minutes. Now that the three minutes is up, take it out of the air fryer, cut it, and give it a try. OCR: That's Good! WITH MONTANA MONTEREY play! RECREATION NG 5<S HONTEREY BINGA ISUR VF 2000 CA QUAS IONTEREY DECREATION BINCNAE 1SUS VIV ). 2021 ONTREY DECRATION DA REC ONTEREY ECREATION /V 20MON REC MONNEY A RECR TION 202 252 MO DA RE 1S8V 2120 BREC 2n2 MON MONTREYY DA Air Fryer Grilled Cheese 2 slices white bread Sharp Cheddar & Italian Blend Cheeses Salted butter X #showushowyouplayMonterey VLM: Visual summary: A young man in a kitchen prepares to make a grilled cheese sandwich using an air fryer. 视觉摘要: 一名年轻男子在厨房里准备使用空气炸锅制作烤奶酪三明治。 Visible product: Air Fryer Visible components: air fryer; refrigerator; wooden cabinets; countertop; knife block; coffee maker; glass jars; mug; red cutting board; bread; apron Visible actions: man standing; man handling bread | N4: 3 | O4: 3 | P4: 47.0 | Q4: 51.0 | R4: cook for four minutes. Now flip it over and then cook for another three minutes. | S4: ASR | T4: low | U4: The ASR text clearly specifies cooking times (4 minutes, then 3 minutes) and is directly tied to the air fryer operation, matching the question's request for temperature and time settings. | V4: R1 | W4: 3 | X4: 47 | Y4: 65 | Z4: no | AA4: 画面显示烤制奶酪三明治的流程，64.7s帧将三明治放入空气炸锅；ASR 中明确提到'cook for four minutes... cook for another three minutes'，语音直接给出了烹饪时间，能回答问题。 | AB4: 复核扩展时间区间至 47-65s，以覆盖证据中 64.7s 将三明治放入空气炸锅的关键帧（原 47-51s 范围偏窄，未含该帧）。 | AC4: completed | AD4: 2026-07-28T13:42:36+08:00 | AE4: =IF(AC4<>"completed","",IF(W4=O4,"no","yes")) | AF4: =IF(AC4<>"completed","",IF(AND(X4=P4,Y4=Q4),"no","yes")) | AG4: =IF(AC4<>"completed","待复核",IF(OR(W4="",Z4="",AA4="",AD4=""),"缺少必填项",IF(AND(OR(AE4="yes",AF4="yes"),AB4=""),"修正原因缺失",IF(OR(W4=0,W4=1),IF(AND(X4="",Y4=""),"通过","0/1级时间应留空"),IF(AND(OR(W4=2,W4=3),X4<>"",Y4<>"",X4>=I4,Y4<=J4,Y4>X4),"通过","2/3级时间无效")))))
A5: VQ-001 | B5: 空气炸锅怎样设置烹饪温度和时间？ | C5: zh-CN | D5: Air Fryer | E5: operation | F5: development | G5: airfryer-029-scene-0066 | H5: airfryer-029 | I5: 403.92 | J5: 405.96 | K5: items/airfryer-029-scene-0066/clip.mp4 | L5: items/airfryer-029-scene-0066/thumbnail.jpg | M5: ASR: also the chicken will be cooked perfectly. This awesome-looking Philips OCR: Philips SUPER CHEF VLM: Visual summary: A close-up of a black Philips air fryer showing its temperature dial and timer dial. 视觉摘要: 一台黑色飞利浦空气炸锅的特写，显示其温度旋钮和计时旋钮。 Visible product: Philips Visible components: temperature dial; timer dial; brand logo; control knobs | N5: 4 | O5: 2 | P5: 403.92 | Q5: 405.96 | R5: The scene shows the temperature and timer dials on a Philips air fryer, visually indicating where temperature and time settings can be adjusted, though no actual setting values or instructions are provided. | S5: VLM|ASR|OCR | T5: low | U5: No spoken or visual instruction on how to set temperature and time is given; only the controls are shown. | V5: R1 | W5: 2 | X5: 403.92 | Y5: 405.96 | Z5: no | AA5: 画面为飞利浦空气炸锅顶部特写，可见温度/时间机械旋钮及刻度（约404.3s），直接展示了设置温度/时间的控制部件，但未演示具体调节过程，属于部分回答。 | AC5: completed | AD5: 2026-07-27T22:01:34+08:00 | AE5: =IF(AC5<>"completed","",IF(W5=O5,"no","yes")) | AF5: =IF(AC5<>"completed","",IF(AND(X5=P5,Y5=Q5),"no","yes")) | AG5: =IF(AC5<>"completed","待复核",IF(OR(W5="",Z5="",AA5="",AD5=""),"缺少必填项",IF(AND(OR(AE5="yes",AF5="yes"),AB5=""),"修正原因缺失",IF(OR(W5=0,W5=1),IF(AND(X5="",Y5=""),"通过","0/1级时间应留空"),IF(AND(OR(W5=2,W5=3),X5<>"",Y5<>"",X5>=I5,Y5<=J5,Y5>X5),"通过","2/3级时间无效")))))
A6: VQ-001 | B6: 空气炸锅怎样设置烹饪温度和时间？ | C6: zh-CN | D6: Air Fryer | E6: operation | F6: development | G6: airfryer-005-scene-0022 | H6: airfryer-005 | I6: 207.465 | J6: 227.314 | K6: items/airfryer-005-scene-0022/clip.mp4 | L6: items/airfryer-005-scene-0022/thumbnail.jpg | M6: ASR: air fryer, the basket goes and then we set the temperature to 350 Fahrenheit and then we just turn it on for 10 minutes and that's it and let it do its thing. And when the timer goes off, you can take it out and look VLM: Visual summary: A man in a kitchen stands behind a black air fryer on a countertop, gesturing and speaking to the camera. 视觉摘要: 一名男子站在厨房的台面上，身后放着一台黑色空气炸锅，他正对着镜头做手势说话。 Visible product: Air Fryer Visible components: black air fryer; stainless steel refrigerator; white kitchen cabinets; glass jars; knife block; paper towel holder; whey protein container; blue funnel Visible actions: man gesturing with hands; man speaking | N6: 5 | O6: 3 | P6: 207.465 | Q6: 227.314 | R6: ASR explicitly states setting temperature to 350 Fahrenheit and timer to 10 minutes, which directly answers the question about air fryer temperature and time settings. | S6: ASR|VLM | T6: low | U6: The ASR provides complete, unambiguous instructions for temperature and time settings, and the VLM confirms the product is an air fryer. | V6: R1 | W6: 3 | X6: 207.465 | Y6: 227.314 | Z6: no | AA6: 画面中一位男士站在空气炸锅前讲解并打开/指向机身；ASR 明确说'set the temperature to 350 Fahrenheit and then we just turn it on for 10 minutes'，语音直接给出了温度与时间的设置，能回答问题。 | AC6: completed | AD6: 2026-07-27T22:01:40+08:00 | AE6: =IF(AC6<>"completed","",IF(W6=O6,"no","yes")) | AF6: =IF(AC6<>"completed","",IF(AND(X6=P6,Y6=Q6),"no","yes")) | AG6: =IF(AC6<>"completed","待复核",IF(OR(W6="",Z6="",AA6="",AD6=""),"缺少必填项",IF(AND(OR(AE6="yes",AF6="yes"),AB6=""),"修正原因缺失",IF(OR(W6=0,W6=1),IF(AND(X6="",Y6=""),"通过","0/1级时间应留空"),IF(AND(OR(W6=2,W6=3),X6<>"",Y6<>"",X6>=I6,Y6<=J6,Y6>X6),"通过","2/3级时间无效")))))
A7: VQ-001 | B7: 空气炸锅怎样设置烹饪温度和时间？ | C7: zh-CN | D7: Air Fryer | E7: operation | F7: development | G7: airfryer-027-scene-0002 | H7: airfryer-027 | I7: 7.508 | J7: 283.4 | K7: items/airfryer-027-scene-0002/clip.mp4 | L7: items/airfryer-027-scene-0002/thumbnail.jpg | M7: ASR: Okay, so first we coat the wings with baking powder, some kosher salt, and a little bit of garlic powder. And we're going to preheat the oven to 450 degrees. So after 25 minutes, we're going to take these, flip them over. And of course, with the traditional version of the oven, we're going to provide some Frank's Red Hot Sauce. real deal butter and a touch of brown sugar and that's what we're gonna of course toss our wings into and for the other wings we're going to use McCormick's air fryer buffalo wings and it supposedly has some kind of authentic Frank's red hot sauce obviously dehydrated powder and we're going to cover these and of course this takes about half the time of the oven-cooked ones and we got our air-fried version here toss with oil and the seasoning the cormac seasoning we're going to throw these babies in here doesn't seem to really cope very well honestly but turn a reminder whoops 20 20 minutes, see what happens. Okay, so here we are. There are two different versions of so-called buffalo wings. On the top we have the oven-baked version, the real Frank's hot sauce, and on the bottom we have the McCormick air fryer version. See, they look completely different. So let's try the oven-baked version first. Nothing like that real French hot sauce with butter or brown sugar. Mmm, very good. A little bit dry, but that's because these are small wings. I would have cooked them a little bit less than 50 minutes, maybe 40 minutes. Not bad. Okay, let's try the air fryer wings. Here we go. Now, in this case, I'm definitely going to dip these in a little bit of ranch dressing here. Let's check it out. Whoops. It's actually not bad. Very tasty. And since it's air fried, it's more, it seems to be evenly cooked. So for all you Buffalo Wing fans out there, the reality is the best Buffalo Wings are deep fried in a deep fryer just like they were when I grew up in Buffalo in the 1970s and tossed in Frank's hot sauce with a bit of butter and as much sugar as you want so sorry health food fans but honestly the air fryer and baked versions they're okay it tastes good but it's not like the original. OCR: WRONRSSH and bake for another 20 minutes OVEN READY McCormick AIR FRYER Buffalo RedHot m AIR FRYER FRANK: NO ARTIFICIAL FLAYORS Esenti MCCORNICE SPICES NO ARTIRICIAL FLAPORS VEN EADY ER Talo table Oil TART courmia Gourmia 3808 * courmia. GOr START 89:39 VLM: Visual summary: Chicken wings are shown cooking on a wire rack over aluminum foil on a stovetop, then plated with a dipping sauce. 视觉摘要: 鸡翅在炉灶上的烤架上烹饪，然后盛放在盘子中，配有一份蘸酱。 Visible product: Air Fryer Visible components: stovetop; gas burner grates; wire rack; aluminum foil; plate; glass cup; black and white checkered tablecloth Visible actions: chicken wings are cooking; a man is speaking to the camera Visible states: chicken wings are cooked and golden brown; dipping sauce is on the plate Visual uncertainty: The specific product being referred to as 'Air Fryer' is not visible in the frames. | N7: 6 | O7: 2 | P7: 27.508 | Q7: 283.4 | R7: ASR mentions '20 minutes' for air fryer cooking time and OCR shows 'AIR FRYER' and 'START' with visible product context, indicating a cooking time setting is implied for the air fryer, though no explicit temperature setting is provided. | S7: ASR|OCR | T7: medium | U7: The ASR mentions a time ('20 minutes') but not a temperature for the air fryer, and OCR does not specify a temperature value, only product context. | V7: R1 | W7: 2 | X7: 110.0 | Y7: 130.0 | Z7: no | AA7: 长视频主要是烤箱烤鸡翅流程，但 117.9s 帧可见空气炸锅显示屏'1934'，说明设备在运行并设有温度时间，但未明确解释如何设置，只能部分回答。 | AB7: 时间按画面中可见的空气炸锅显示区收窄至 t≈110-130s。 | AC7: completed | AD7: 2026-07-27T22:01:40+08:00 | AE7: =IF(AC7<>"completed","",IF(W7=O7,"no","yes")) | AF7: =IF(AC7<>"completed","",IF(AND(X7=P7,Y7=Q7),"no","yes")) | AG7: =IF(AC7<>"completed","待复核",IF(OR(W7="",Z7="",AA7="",AD7=""),"缺少必填项",IF(AND(OR(AE7="yes",AF7="yes"),AB7=""),"修正原因缺失",IF(OR(W7=0,W7=1),IF(AND(X7="",Y7=""),"通过","0/1级时间应留空"),IF(AND(OR(W7=2,W7=3),X7<>"",Y7<>"",X7>=I7,Y7<=J7,Y7>X7),"通过","2/3级时间无效")))))
A8: VQ-001 | B8: 空气炸锅怎样设置烹饪温度和时间？ | C8: zh-CN | D8: Air Fryer | E8: operation | F8: development | G8: airfryer-029-scene-0055 | H8: airfryer-029 | I8: 324.32 | J8: 326.44 | K8: items/airfryer-029-scene-0055/clip.mp4 | L8: items/airfryer-029-scene-0055/thumbnail.jpg | M8: ASR: degree centigrade for around 10 minutes using Philips air fryer anybody can cook OCR: PHILIPS SUPER CHEF VLM: Visual summary: A close-up of a black Philips air fryer showing its control dial and cooking guide label. 视觉摘要: 一台黑色飞利浦空气炸锅的特写，显示其控制旋钮和烹饪指南标签。 Visible product: Air Fryer Visible components: control dial; brand name 'PHILIPS'; cooking guide label with temperature and time icons; temperature indicator (200°C) | N8: 7 | O8: 2 | P8: 324.32 | Q8: 326.44 | R8: The visual shows the control dial and temperature indicator (200°C), and ASR mentions setting temperature and time (e.g., 10 minutes), indicating adjacent steps for operation, but no explicit step-by-step instruction is shown or spoken. | S8: VLM|ASR|OCR | T8: low | U8: No explicit step-by-step instruction for setting temperature and time is provided, but the visual and ASR context imply the capability to set these parameters. | V8: R1 | W8: 3 | X8: 324.32 | Y8: 326.44 | Z8: no | AA8: 画面中清晰展示手指旋转飞利浦空气炸锅的温度/时间旋钮，并可见烹饪指南图标（含温度、时间、食材图标），直接演示了如何设置温度和时间。 | AB8: AI预标2级，但画面直接展示旋钮设置动作，能直接回答问题，修正为3级。 | AC8: completed | AD8: 2026-07-27T22:01:40+08:00 | AE8: =IF(AC8<>"completed","",IF(W8=O8,"no","yes")) | AF8: =IF(AC8<>"completed","",IF(AND(X8=P8,Y8=Q8),"no","yes")) | AG8: =IF(AC8<>"completed","待复核",IF(OR(W8="",Z8="",AA8="",AD8=""),"缺少必填项",IF(AND(OR(AE8="yes",AF8="yes"),AB8=""),"修正原因缺失",IF(OR(W8=0,W8=1),IF(AND(X8="",Y8=""),"通过","0/1级时间应留空"),IF(AND(OR(W8=2,W8=3),X8<>"",Y8<>"",X8>=I8,Y8<=J8,Y8>X8),"通过","2/3级时间无效")))))
A9: VQ-001 | B9: 空气炸锅怎样设置烹饪温度和时间？ | C9: zh-CN | D9: Air Fryer | E9: operation | F9: development | G9: airfryer-017-scene-0101 | H9: airfryer-017 | I9: 1370.736 | J9: 1398.664 | K9: items/airfryer-017-scene-0101/clip.mp4 | L9: items/airfryer-017-scene-0101/thumbnail.jpg | M9: ASR: Now I'm going to do something. I don't know if this is safe, so don't try this at home, but before I reassemble this entire unit, I'm going to take my two power cords. I'm gonna plug them back into my switch and I'm gonna plug the unit back into the wall See if I can power this thing on just to make sure it's working before I spend all the time to screw everything back together And moment of truth as power it's giving me an e1 message, but I already know what it means It means that I forgot to plug the thermistor back into the circuit panel OCR: 3 11 UNIT APROFESSIONA 18 I'M NOT DON'T TRY THIS AT HOMI COUNT 19 VLM: Visual summary: A disassembled black appliance, labeled as an air fryer, is on a table with a person's hand interacting with its internal wiring and components. Tools and paper are scattered around. 视觉摘要: 一台被拆开的黑色空气炸锅放在桌子上，一个人的手正在操作其内部的电线和部件，周围散落着工具和纸张。 Visible product: Air Fryer Visible components: black appliance chassis; internal wiring; small circuit board; fan; control panel; screwdriver; pliers; paper; cardboard box Visible actions: hand holding wires; hand manipulating a wire connector Visible states: appliance disassembled; control panel lit with blue display Visible warnings: I'M NOT A PROFESSIONAL. DON'T TRY THIS AT HOME. | N9: 8 | O9: 0 | R9: The scene shows a disassembled air fryer with internal wiring and a control panel lit, but no visible or spoken content about setting temperature or time. The ASR discusses troubleshooting an error message and reassembling the unit, not operation settings. The OCR includes a warning and partial text unrelated to cooking settings. | S9: VLM|ASR|OCR | T9: low | U9: No evidence of temperature or time setting actions or instructions visible or audible in the scene. | V9: R1 | W9: 0 | Z9: no | AA9: 画面为拆解中的空气炸锅内部线路与控制板，与设置温度/时间无关。 | AC9: completed | AD9: 2026-07-27T22:01:40+08:00 | AE9: =IF(AC9<>"completed","",IF(W9=O9,"no","yes")) | AF9: =IF(AC9<>"completed","",IF(AND(X9=P9,Y9=Q9),"no","yes")) | AG9: =IF(AC9<>"completed","待复核",IF(OR(W9="",Z9="",AA9="",AD9=""),"缺少必填项",IF(AND(OR(AE9="yes",AF9="yes"),AB9=""),"修正原因缺失",IF(OR(W9=0,W9=1),IF(AND(X9="",Y9=""),"通过","0/1级时间应留空"),IF(AND(OR(W9=2,W9=3),X9<>"",Y9<>"",X9>=I9,Y9<=J9,Y9>X9),"通过","2/3级时间无效")))))
A10: VQ-001 | B10: 空气炸锅怎样设置烹饪温度和时间？ | C10: zh-CN | D10: Air Fryer | E10: operation | F10: development | G10: airfryer-002-scene-0001 | H10: airfryer-002 | I10: 0.0 | J10: 11.044 | K10: items/airfryer-002-scene-0001/clip.mp4 | L10: items/airfryer-002-scene-0001/thumbnail.jpg | M10: OCR: The Library Kitchen Lärary Kiehen Air I Fryer Oreos www.gloucesterva.info/publiclibrary Chef Library Kitchen Puff Pastry SHEETS OREO VLM: Visual summary: Three powdered pastries are on a white plate with a fork, overlaid with text identifying the content as 'The Library Kitchen' and 'Air Fryer Oreos'. 视觉摘要: 白色盘子上有三个撒了粉的糕点，旁边放着一把叉子，叠加的文字显示内容为“图书馆厨房”和“空气炸锅奥利奥”。 Visible product: Air Fryer Oreos Visible components: white plate; fork; pastries; powder; text overlay | N10: 9 | O10: 0 | R10: The scene shows prepared pastries with text overlay identifying the product as 'Air Fryer Oreos', but provides no visual, spoken, or OCR evidence of temperature or time settings for cooking. | S10: VLM|OCR | T10: low | U10: No evidence of cooking settings or instructions is present in the scene. | V10: R1 | W10: 0 | Z10: no | AA10: 画面仅展示成品甜点与文字“Air Fryer Oreos”，未出现空气炸锅本体、控制面板或温度/时间设置操作。 | AC10: completed | AD10: 2026-07-27T22:10:25+08:00 | AE10: =IF(AC10<>"completed","",IF(W10=O10,"no","yes")) | AF10: =IF(AC10<>"completed","",IF(AND(X10=P10,Y10=Q10),"no","yes")) | AG10: =IF(AC10<>"completed","待复核",IF(OR(W10="",Z10="",AA10="",AD10=""),"缺少必填项",IF(AND(OR(AE10="yes",AF10="yes"),AB10=""),"修正原因缺失",IF(OR(W10=0,W10=1),IF(AND(X10="",Y10=""),"通过","0/1级时间应留空"),IF(AND(OR(W10=2,W10=3),X10<>"",Y10<>"",X10>=I10,Y10<=J10,Y10>X10),"通过","2/3级时间无效")))))
A11: VQ-001 | B11: 空气炸锅怎样设置烹饪温度和时间？ | C11: zh-CN | D11: Air Fryer | E11: operation | F11: development | G11: airfryer-024-scene-0020 | H11: airfryer-024 | I11: 85.852 | J11: 93.56 | K11: items/airfryer-024-scene-0020/clip.mp4 | L11: items/airfryer-024-scene-0020/thumbnail.jpg | M11: ASR: Why settle for inaccurate knobs and analog dials? Just guessing. The New Wave Brio is the only air fryer with precise temperature control. Simply use the digital touchscreen and cook from 100 degrees to 400 degrees in 5 degree increments. OCR: PRECISE nuwave Temperature 360Y 360F 3007 Control 3 756 TM VLM: Visual summary: A hand is shown adjusting a dial on a kitchen appliance, followed by a finger pressing buttons on a digital air fryer control panel. 视觉摘要: 一只手正在调整厨房电器上的旋钮，随后手指按压空气炸锅控制面板上的按钮。 Visible product: nuwave Visible components: hand; dial; air fryer; digital display; control buttons; temperature settings; food icons Visible actions: adjusting a dial; pressing a button Visible states: digital display showing 375F; dial set to 5 | N11: 10 | O11: 3 | P11: 85.852 | Q11: 93.56 | R11: ASR states the air fryer has precise digital temperature control from 100 to 400 degrees in 5-degree increments. OCR shows temperature settings (360Y, 360F, 3007) and VLM shows hand adjusting dial and pressing buttons on digital panel with display showing 375F, confirming temperature setting action. | S11: ASR|OCR|VLM | T11: low | U11: All evidence directly supports setting temperature and time via digital interface with visible actions and text. | V11: R1 | W11: 3 | X11: 86.0 | Y11: 93.56 | Z11: no | AA11: 画面显示手指拨动/按压空气炸锅温度旋钮与数字面板，OCR可见380F/375F及PRECISE Temperature Control，ASR说明100-400度5度递增的精确温控，可直接回答温度设置。 | AB11: 时间按实际证据片段重定位 | AC11: completed | AD11: 2026-07-27T22:10:25+08:00 | AE11: =IF(AC11<>"completed","",IF(W11=O11,"no","yes")) | AF11: =IF(AC11<>"completed","",IF(AND(X11=P11,Y11=Q11),"no","yes")) | AG11: =IF(AC11<>"completed","待复核",IF(OR(W11="",Z11="",AA11="",AD11=""),"缺少必填项",IF(AND(OR(AE11="yes",AF11="yes"),AB11=""),"修正原因缺失",IF(OR(W11=0,W11=1),IF(AND(X11="",Y11=""),"通过","0/1级时间应留空"),IF(AND(OR(W11=2,W11=3),X11<>"",Y11<>"",X11>=I11,Y11<=J11,Y11>X11),"通过","2/3级时间无效")))))
A12: VQ-001 | B12: 空气炸锅怎样设置烹饪温度和时间？ | C12: zh-CN | D12: Air Fryer | E12: operation | F12: development | G12: airfryer-005-scene-0026 | H12: airfryer-005 | I12: 243.87 | J12: 266.222 | K12: items/airfryer-005-scene-0026/clip.mp4 | L12: items/airfryer-005-scene-0026/thumbnail.jpg | M12: ASR: Now, depending on your bacon, if it's really thick, you're going to want to probably cook it like you'll form it in like the basket and just put that by itself in the basket and cook it for a few minutes first, just because if it's really thick, 10 minutes is not long enough to cook it, cook it all the way. And any longer than 10 minutes is a little bit too long to cook the egg. OK, just keep that in mind. Just depends on the type of bacon that you're using. thing. VLM: Visual summary: A man in a kitchen stands behind a counter with an air fryer and its basket, gesturing as if explaining or demonstrating the appliance. 视觉摘要: 一名男子站在厨房的台面后，面前放着一个空气炸锅及其炸篮，他正在做手势，似乎在讲解或演示该设备。 Visible product: Air Fryer Visible components: air fryer; air fryer basket; refrigerator; white kitchen cabinets; glass jars; knife block; paper towel holder; sink; protein powder container; blue funnel Visible actions: man gesturing with hands; man speaking | N12: 11 | O12: 1 | R12: The ASR mentions cooking bacon for a few minutes or 10 minutes, implying a time setting, but does not specify how to set temperature or time on the air fryer. The VLM shows a man gesturing while explaining, but no visible interaction with controls or settings. | S12: VLM|ASR | T12: low | U12: No visible or spoken evidence of temperature or time setting on the air fryer controls. | V12: R1 | W12: 1 | Z12: no | AA12: 画面中只有主持人站立讲解，未见操作控制面板，ASR仅提到培根烹饪时间建议，未说明如何设置温度/时间。 | AC12: completed | AD12: 2026-07-27T22:10:25+08:00 | AE12: =IF(AC12<>"completed","",IF(W12=O12,"no","yes")) | AF12: =IF(AC12<>"completed","",IF(AND(X12=P12,Y12=Q12),"no","yes")) | AG12: =IF(AC12<>"completed","待复核",IF(OR(W12="",Z12="",AA12="",AD12=""),"缺少必填项",IF(AND(OR(AE12="yes",AF12="yes"),AB12=""),"修正原因缺失",IF(OR(W12=0,W12=1),IF(AND(X12="",Y12=""),"通过","0/1级时间应留空"),IF(AND(OR(W12=2,W12=3),X12<>"",Y12<>"",X12>=I12,Y12<=J12,Y12>X12),"通过","2/3级时间无效")))))
A13: VQ-001 | B13: 空气炸锅怎样设置烹饪温度和时间？ | C13: zh-CN | D13: Air Fryer | E13: operation | F13: development | G13: airfryer-005-scene-0025 | H13: airfryer-005 | I13: 239.199 | J13: 243.87 | K13: items/airfryer-005-scene-0025/clip.mp4 | L13: items/airfryer-005-scene-0025/thumbnail.jpg | M13: ASR: oil. Now, depending on your bacon, if it's really thick, you're VLM: Visual summary: Two pieces of bread with eggs and bacon are inside an air fryer basket. 视觉摘要: 两个夹有鸡蛋和培根的面包片放在空气炸锅篮子里。 Visible product: Air Fryer Visible components: air fryer basket; bread; egg; bacon; pepper | N13: 12 | O13: 1 | R13: The scene shows bread with eggs and bacon in an air fryer basket, indicating the product is present but no temperature or time settings are visible or mentioned. | S13: VLM | T13: low | U13: No evidence of temperature or time settings being set or discussed. | V13: R1 | W13: 1 | Z13: no | AA13: 画面仅展示炸篮内放有面包、鸡蛋和培根，未出现温度或时间设置界面/操作。 | AC13: completed | AD13: 2026-07-27T22:10:25+08:00 | AE13: =IF(AC13<>"completed","",IF(W13=O13,"no","yes")) | AF13: =IF(AC13<>"completed","",IF(AND(X13=P13,Y13=Q13),"no","yes")) | AG13: =IF(AC13<>"completed","待复核",IF(OR(W13="",Z13="",AA13="",AD13=""),"缺少必填项",IF(AND(OR(AE13="yes",AF13="yes"),AB13=""),"修正原因缺失",IF(OR(W13=0,W13=1),IF(AND(X13="",Y13=""),"通过","0/1级时间应留空"),IF(AND(OR(W13=2,W13=3),X13<>"",Y13<>"",X13>=I13,Y13<=J13,Y13>X13),"通过","2/3级时间无效")))))
A14: VQ-001 | B14: 空气炸锅怎样设置烹饪温度和时间？ | C14: zh-CN | D14: Air Fryer | E14: operation | F14: development | G14: airfryer-017-scene-0022 | H14: airfryer-017 | I14: 164.264 | J14: 172.005 | K14: items/airfryer-017-scene-0022/clip.mp4 | L14: items/airfryer-017-scene-0022/thumbnail.jpg | M14: ASR: The major problem, as I found out a few months ago, was that one time the door fell open while I was cooking. So I'll be sure to tighten up the door during this process. process. First thing I'm going to do is remove these cooking trays. There we go. You can see my OCR: 2 ESES VLM: Visual summary: A hand opens the lid of a black and stainless steel air fryer sitting on a dark wooden table in a dining room. 视觉摘要: 一只手在餐厅的深色木桌上打开一个黑色和不锈钢空气炸锅的盖子。 Visible product: Air Fryer Visible components: air fryer; stainless steel exterior; black lid; dark wooden table; chairs; window with blinds; wall decorations; stuffed animals; dollhouse Visible actions: hand opening the air fryer lid Visible states: air fryer lid open; air fryer interior visible | N14: 13 | O14: 0 | R14: The scene shows a hand opening the air fryer lid, but no temperature or time settings are visible, spoken, or indicated. | S14: VLM | T14: low | U14: No evidence of temperature or time settings being set or discussed. | V14: R1 | W14: 0 | Z14: no | AA14: 画面仅展示打开空气炸锅盖并取出烤盘，未出现温度/时间设置界面或操作。 | AC14: completed | AD14: 2026-07-27T22:12:04+08:00 | AE14: =IF(AC14<>"completed","",IF(W14=O14,"no","yes")) | AF14: =IF(AC14<>"completed","",IF(AND(X14=P14,Y14=Q14),"no","yes")) | AG14: =IF(AC14<>"completed","待复核",IF(OR(W14="",Z14="",AA14="",AD14=""),"缺少必填项",IF(AND(OR(AE14="yes",AF14="yes"),AB14=""),"修正原因缺失",IF(OR(W14=0,W14=1),IF(AND(X14="",Y14=""),"通过","0/1级时间应留空"),IF(AND(OR(W14=2,W14=3),X14<>"",Y14<>"",X14>=I14,Y14<=J14,Y14>X14),"通过","2/3级时间无效")))))
A15: VQ-001 | B15: 空气炸锅怎样设置烹饪温度和时间？ | C15: zh-CN | D15: Air Fryer | E15: operation | F15: development | G15: airfryer-017-scene-0059 | H15: airfryer-017 | I15: 690.49 | J15: 696.062 | K15: items/airfryer-017-scene-0059/clip.mp4 | L15: items/airfryer-017-scene-0059/thumbnail.jpg | M15: ASR: what you can find on eBay. I found two replacements that I guess had been scavenged from other units that were sold in a lot on eBay. The one on the left you see is the larger of the two. I thought OCR: FS Dud thermister +tive wome scrar I ditnit pw buek ind replaen the mister(3) neatng grate wonlert Fit afte I adjured meariy cknt t. acwOmlate A thermirtor Nov. 2022 2 VLM: Visual summary: A product listing for replacement thermistor temperature sensors for a Kalorik MAXX Air Fryer, priced at $19.95, with an image of the part and a 'Unit 8 Count' label appearing in one frame. 视觉摘要: 一个用于Kalorik MAXX空气炸锅的替换温度传感器（热敏电阻）的产品列表，价格为19.95美元，其中一帧显示了“8件装”的标签。 Visible product: Kalorik MAXX Air Fryer ~ REPLACEMENT PARTS ~ Thermistor - temperature sensors Visible components: image of two metal thermistor sensors with wires; text label 'UNIT 8 COUNT' Visual uncertainty: The 'UNIT 8 COUNT' label is only visible in the second frame, not the first. | N15: 14 | O15: 0 | R15: The scene shows a product listing for replacement thermistors for a Kalorik MAXX Air Fryer, not instructions on setting temperature and time. | S15: VLM|ASR|OCR | T15: low | U15: The evidence clearly shows a replacement part listing, not operational guidance for setting temperature or time. | V15: R1 | W15: 0 | Z15: no | AA15: 画面为 eBay 商品列表页（温度传感器替换件），非操作教学。 | AC15: completed | AD15: 2026-07-27T22:12:04+08:00 | AE15: =IF(AC15<>"completed","",IF(W15=O15,"no","yes")) | AF15: =IF(AC15<>"completed","",IF(AND(X15=P15,Y15=Q15),"no","yes")) | AG15: =IF(AC15<>"completed","待复核",IF(OR(W15="",Z15="",AA15="",AD15=""),"缺少必填项",IF(AND(OR(AE15="yes",AF15="yes"),AB15=""),"修正原因缺失",IF(OR(W15=0,W15=1),IF(AND(X15="",Y15=""),"通过","0/1级时间应留空"),IF(AND(OR(W15=2,W15=3),X15<>"",Y15<>"",X15>=I15,Y15<=J15,Y15>X15),"通过","2/3级时间无效")))))
A16: VQ-001 | B16: 空气炸锅怎样设置烹饪温度和时间？ | C16: zh-CN | D16: Air Fryer | E16: operation | F16: development | G16: airfryer-017-scene-0061 | H16: airfryer-017 | I16: 705.038 | J16: 724.891 | K16: items/airfryer-017-scene-0061/clip.mp4 | L16: items/airfryer-017-scene-0061/thumbnail.jpg | M16: ASR: two sizes. That's the one that's currently in my air fryer. I'm going to go ahead and test this this other replacement one that I haven't used yet for continuity, just to see. And since I'm not seeing any continuity on this thermistor, I'm not sure that that's something I should be looking for. Last time I replaced the thermistor just because I thought it was something I should do, but now I'm realizing that maybe I didn't even have to at the time. So I'm just going to replace the fuse by itself first and see if that does the trick. This is where getting deeper into OCR: TADIES 22 Frper Emeril Air parts USPS FIRST-CLASS PKG 2 Nov.22 F VLM: Visual summary: A person is using a multimeter to test a small blue electrical component held in their hand, with the component connected to wires. The setup is on a wooden table with various items including a USPS package labeled 'Emeril Air Fryer parts' and a red Staples box. 视觉摘要: 一个人正用万用表测试手中拿着的一个小蓝色电气元件，该元件连接着电线。设置在一张木桌上，周围有各种物品，包括一个标有“Emeril Air Fryer parts”的USPS包裹和一个红色的Staples盒子。 Visible product: Air Fryer Visible components: multimeter; blue electrical component; wires; USPS package; Staples box; wooden table Visible actions: person holding component; person using multimeter probes | N16: 15 | O16: 0 | R16: The scene shows troubleshooting of an air fryer component (thermistor/fuse) using a multimeter, not setting temperature or time. | S16: VLM|ASR|OCR | T16: low | U16: No evidence of temperature or time setting actions or instructions. | V16: R1 | W16: 0 | Z16: no | AA16: 画面为用万用表检测温度保险丝/热敏电阻，未涉及温度或时间设置。 | AC16: completed | AD16: 2026-07-27T22:12:04+08:00 | AE16: =IF(AC16<>"completed","",IF(W16=O16,"no","yes")) | AF16: =IF(AC16<>"completed","",IF(AND(X16=P16,Y16=Q16),"no","yes")) | AG16: =IF(AC16<>"completed","待复核",IF(OR(W16="",Z16="",AA16="",AD16=""),"缺少必填项",IF(AND(OR(AE16="yes",AF16="yes"),AB16=""),"修正原因缺失",IF(OR(W16=0,W16=1),IF(AND(X16="",Y16=""),"通过","0/1级时间应留空"),IF(AND(OR(W16=2,W16=3),X16<>"",Y16<>"",X16>=I16,Y16<=J16,Y16>X16),"通过","2/3级时间无效")))))
A17: VQ-001 | B17: 空气炸锅怎样设置烹饪温度和时间？ | C17: zh-CN | D17: Air Fryer | E17: operation | F17: development | G17: airfryer-032-scene-0040 | H17: airfryer-032 | I17: 179.167 | J17: 182.167 | K17: items/airfryer-032-scene-0040/clip.mp4 | L17: items/airfryer-032-scene-0040/thumbnail.jpg | M17: ASR: to ten minutes at 400 degrees. You might have to do this a few times before the smell goes away. If the smell is too bothersome, you can set it outside in a safe spot and run it out there for VLM: Visual summary: A hand opens the drawer of a black air fryer, revealing a small bowl inside the basket. 视觉摘要: 一只手打开黑色空气炸锅的抽屉，露出篮子内的一只小碗。 Visible product: Air Fryer Visible components: black air fryer; air fryer basket; air fryer drawer handle; small bowl; green bottle; marble countertop Visible actions: hand pulling open drawer Visible states: drawer open; basket revealed | N17: 16 | O17: 1 | R17: ASR mentions temperature (400 degrees) and time (10 minutes) for air fryer operation, but VLM shows only drawer opening with no temperature or time setting action; no visible or spoken evidence of setting temperature/time in this scene. | S17: ASR|VLM | T17: low | U17: ASR provides temperature and time values but no visual evidence of setting them; VLM shows no interaction with controls. | V17: R1 | W17: 1 | Z17: no | AA17: ASR提到400度10分钟，但画面仅展示拉开抽屉，未展示设置温度/时间的操作。 | AC17: completed | AD17: 2026-07-27T22:12:04+08:00 | AE17: =IF(AC17<>"completed","",IF(W17=O17,"no","yes")) | AF17: =IF(AC17<>"completed","",IF(AND(X17=P17,Y17=Q17),"no","yes")) | AG17: =IF(AC17<>"completed","待复核",IF(OR(W17="",Z17="",AA17="",AD17=""),"缺少必填项",IF(AND(OR(AE17="yes",AF17="yes"),AB17=""),"修正原因缺失",IF(OR(W17=0,W17=1),IF(AND(X17="",Y17=""),"通过","0/1级时间应留空"),IF(AND(OR(W17=2,W17=3),X17<>"",Y17<>"",X17>=I17,Y17<=J17,Y17>X17),"通过","2/3级时间无效")))))
A18: VQ-001 | B18: 空气炸锅怎样设置烹饪温度和时间？ | C18: zh-CN | D18: Air Fryer | E18: operation | F18: development | G18: airfryer-005-scene-0027 | H18: airfryer-005 | I18: 266.222 | J18: 270.142 | K18: items/airfryer-005-scene-0027/clip.mp4 | L18: items/airfryer-005-scene-0027/thumbnail.jpg | M18: ASR: thing. And that is just awesome. And now I'm going to just grab this. VLM: Visual summary: Two pieces of bread with eggs and bacon are placed inside an air fryer basket. 视觉摘要: 两个放有鸡蛋和培根的面包片放在空气炸锅篮子里。 Visible product: Air Fryer Visible components: air fryer basket; bread; egg; bacon; seasoning Visible actions: hand holding air fryer handle | N18: 17 | O18: 1 | R18: The scene shows bread with eggs and bacon placed in an air fryer basket, indicating the product is being prepared for cooking, but no temperature or time settings are visible or mentioned. | S18: VLM | T18: low | U18: No evidence of temperature or time settings being adjusted or displayed. | V18: R1 | W18: 1 | Z18: no | AA18: 画面仅展示炸篮内放有面包、鸡蛋和培根，未展示温度或时间设置。 | AC18: completed | AD18: 2026-07-27T22:14:31+08:00 | AE18: =IF(AC18<>"completed","",IF(W18=O18,"no","yes")) | AF18: =IF(AC18<>"completed","",IF(AND(X18=P18,Y18=Q18),"no","yes")) | AG18: =IF(AC18<>"completed","待复核",IF(OR(W18="",Z18="",AA18="",AD18=""),"缺少必填项",IF(AND(OR(AE18="yes",AF18="yes"),AB18=""),"修正原因缺失",IF(OR(W18=0,W18=1),IF(AND(X18="",Y18=""),"通过","0/1级时间应留空"),IF(AND(OR(W18=2,W18=3),X18<>"",Y18<>"",X18>=I18,Y18<=J18,Y18>X18),"通过","2/3级时间无效")))))
A19: VQ-001 | B19: 空气炸锅怎样设置烹饪温度和时间？ | C19: zh-CN | D19: Air Fryer | E19: operation | F19: development | G19: airfryer-006-scene-0001 | H19: airfryer-006 | I19: 0.0 | J19: 4.538 | K19: items/airfryer-006-scene-0001/clip.mp4 | L19: items/airfryer-006-scene-0001/thumbnail.jpg | M19: ASR: Hi, good morning, America. It's Babs making air fryer Oreos. Step one, crescent rolls. OCR: GMA making Air Fryer Oreos! VLM: Visual summary: A woman in a pink shirt is speaking to the camera in a kitchen setting, introducing herself as 'Babs' and mentioning she is making 'Air Fryer Oreos'. 视觉摘要: 一位穿着粉色衬衫的女士在厨房环境中对着镜头讲话，介绍自己为“Babs”，并提到她正在制作“空气炸锅奥利奥”。 Visible product: Air Fryer Visible components: woman; pink shirt; glasses; kitchen counter; stacked plates; wooden shelf; GMA logo Visible actions: speaking; looking at camera | N19: 18 | O19: 1 | R19: The scene introduces the product (Air Fryer) and the creator (Babs) but does not show or mention any temperature or time settings for cooking. | S19: VLM|ASR|OCR | T19: low | U19: No evidence of temperature or time settings being discussed or demonstrated. | V19: R1 | W19: 0 | Z19: no | AA19: 画面为人物开场白与手持食材，未见空气炸锅本体或温度/时间设置操作。 | AB19: AI原判为1级，但画面中无空气炸锅实体，仅为食谱引入，故降为0级。 | AC19: completed | AD19: 2026-07-27T22:14:31+08:00 | AE19: =IF(AC19<>"completed","",IF(W19=O19,"no","yes")) | AF19: =IF(AC19<>"completed","",IF(AND(X19=P19,Y19=Q19),"no","yes")) | AG19: =IF(AC19<>"completed","待复核",IF(OR(W19="",Z19="",AA19="",AD19=""),"缺少必填项",IF(AND(OR(AE19="yes",AF19="yes"),AB19=""),"修正原因缺失",IF(OR(W19=0,W19=1),IF(AND(X19="",Y19=""),"通过","0/1级时间应留空"),IF(AND(OR(W19=2,W19=3),X19<>"",Y19<>"",X19>=I19,Y19<=J19,Y19>X19),"通过","2/3级时间无效")))))
A20: VQ-001 | B20: 空气炸锅怎样设置烹饪温度和时间？ | C20: zh-CN | D20: Air Fryer | E20: operation | F20: development | G20: airfryer-033-scene-0157 | H20: airfryer-033 | I20: 1391.658 | J20: 1408.108 | K20: items/airfryer-033-scene-0157/clip.mp4 | L20: items/airfryer-033-scene-0157/thumbnail.jpg | M20: ASR: Cheguei, de banhozinho tomado OCR: PHILIPS WALITA D K VLM: Visual summary: A black air fryer with a digital display is shown, with the temperature and timer settings changing on the screen. 视觉摘要: 一台黑色空气炸锅，其数字显示屏上的温度和计时器设置正在变化。 Visible product: Air Fryer Visible components: digital display; temperature control buttons; timer control buttons; power button; brand name 'PHILIPS WALITA'; air fryer basket; control panel; power cord Visible actions: temperature setting changing; timer setting changing Visible states: display showing '200°'; display showing '5'; display showing '0' | N20: 19 | O20: 3 | P20: 1391.658 | Q20: 1408.108 | R20: The air fryer's digital display shows temperature and timer settings changing, including '200°' and '5', indicating direct demonstration of setting temperature and time. | S20: VLM|ASR|OCR | T20: low | U20: No ambiguity in visible actions or displayed values; full scene interval is supported by visual and OCR evidence. | V20: R1 | W20: 2 | X20: 1391.7 | Y20: 1408.1 | Z20: no | AA20: 6帧中飞利浦空气炸锅数字显示屏持续可见并显示变化数字，但未清晰呈现手指按压温度/时间按键的设置动作。 | AB20: 第三轮双复核一致修正：R1=3→indep=2：画面仅展示数字屏上的设置结果/倒计时，未完整演示“如何设置”温度与时间的按键操作。 | AC20: completed | AD20: 2026-07-28T20:35:21+08:00 | AE20: =IF(AC20<>"completed","",IF(W20=O20,"no","yes")) | AF20: =IF(AC20<>"completed","",IF(AND(X20=P20,Y20=Q20),"no","yes")) | AG20: =IF(AC20<>"completed","待复核",IF(OR(W20="",Z20="",AA20="",AD20=""),"缺少必填项",IF(AND(OR(AE20="yes",AF20="yes"),AB20=""),"修正原因缺失",IF(OR(W20=0,W20=1),IF(AND(X20="",Y20=""),"通过","0/1级时间应留空"),IF(AND(OR(W20=2,W20=3),X20<>"",Y20<>"",X20>=I20,Y20<=J20,Y20>X20),"通过","2/3级时间无效")))))
A21: VQ-001 | B21: 空气炸锅怎样设置烹饪温度和时间？ | C21: zh-CN | D21: Air Fryer | E21: operation | F21: development | G21: airfryer-029-scene-0008 | H21: airfryer-029 | I21: 38.0 | J21: 43.92 | K21: items/airfryer-029-scene-0008/clip.mp4 | L21: items/airfryer-029-scene-0008/thumbnail.jpg | M21: ASR: air fryer also. With Philips air fryer unique rapid air technology you can fry OCR: PHILIPS VLM: Visual summary: A close-up of a black Philips air fryer with its control dial and a partially visible basket. 视觉摘要: 一台黑色飞利浦空气炸锅的特写，显示其控制旋钮和部分可见的炸篮。 Visible product: Air Fryer Visible components: Philips brand logo; control dial; air fryer basket; temperature and time settings label Visible states: air fryer basket partially open | N21: 20 | O21: 1 | R21: The scene shows the air fryer's control dial and temperature/time settings label, indicating the product is visible but no actual setting or adjustment is demonstrated. | S21: VLM | T21: low | U21: No action of setting temperature or time is shown; only the interface is visible. | V21: R1 | W21: 1 | Z21: no | AA21: 画面展示飞利浦空气炸锅的控制旋钮与温度/时间刻度，但未演示实际调节动作。 | AC21: completed | AD21: 2026-07-27T22:14:31+08:00 | AE21: =IF(AC21<>"completed","",IF(W21=O21,"no","yes")) | AF21: =IF(AC21<>"completed","",IF(AND(X21=P21,Y21=Q21),"no","yes")) | AG21: =IF(AC21<>"completed","待复核",IF(OR(W21="",Z21="",AA21="",AD21=""),"缺少必填项",IF(AND(OR(AE21="yes",AF21="yes"),AB21=""),"修正原因缺失",IF(OR(W21=0,W21=1),IF(AND(X21="",Y21=""),"通过","0/1级时间应留空"),IF(AND(OR(W21=2,W21=3),X21<>"",Y21<>"",X21>=I21,Y21<=J21,Y21>X21),"通过","2/3级时间无效")))))
A22: VQ-001 | B22: 空气炸锅怎样设置烹饪温度和时间？ | C22: zh-CN | D22: Air Fryer | E22: operation | F22: development | G22: airfryer-002-scene-0008 | H22: airfryer-002 | I22: 191.625 | J22: 241.808 | K22: items/airfryer-002-scene-0008/clip.mp4 | L22: items/airfryer-002-scene-0008/thumbnail.jpg | M22: ASR: bend that seal over and underneath on the bottom of the cookie. At that point you're going to put up just a little bit of an egg wash on the top and continue with all of your cookies. So I'm finishing up making my last cookie to put into the air fryer and you're going to want to preheat your fryer to 350 degrees and we're going to cook these for about seven minutes. So let's get that turned on and preheat it to 350. so our air fryer is preheated to 350 degrees we're going to take the basket out and spray it with a little non-stick spray we're now going to place our cookies in the basket seam side down we're going to cook OCR: Chef Library Kitchen Puff Pastry SHEETS OREO Lhrary Kitche Tray Library Kitchen VLM: Visual summary: A man in a blue apron is preparing food in a kitchen, with ingredients and an air fryer on the counter. 视觉摘要: 一名穿着蓝色围裙的男子在厨房准备食物，台面上有食材和空气炸锅。 Visible product: Air Fryer Visible components: air fryer; puff pastry box; OREO cookies package; powdered sugar container; silicone mat; plate with cookies; apron; glasses Visible actions: man shaping dough; man holding a spray can and a pan Visible states: dough pieces on mat; cookies on plate | N22: 21 | O22: 3 | P22: 230.0 | Q22: 235.0 | R22: ASR states: 'you're going to want to preheat your fryer to 350 degrees and we're going to cook these for about seven minutes.' This directly specifies temperature (350 degrees) and time (7 minutes) for air fryer operation. | S22: ASR | T22: low | U22: The ASR text clearly and fully specifies both temperature and time for the air fryer, with no ambiguity or missing context. | V22: R1 | W22: 3 | X22: 230.0 | Y22: 235.0 | Z22: no | AA22: ASR明确说明需预热至350度并烹饪约7分钟，给出具体温度与时间参数。 | AC22: completed | AD22: 2026-07-27T22:17:08+08:00 | AE22: =IF(AC22<>"completed","",IF(W22=O22,"no","yes")) | AF22: =IF(AC22<>"completed","",IF(AND(X22=P22,Y22=Q22),"no","yes")) | AG22: =IF(AC22<>"completed","待复核",IF(OR(W22="",Z22="",AA22="",AD22=""),"缺少必填项",IF(AND(OR(AE22="yes",AF22="yes"),AB22=""),"修正原因缺失",IF(OR(W22=0,W22=1),IF(AND(X22="",Y22=""),"通过","0/1级时间应留空"),IF(AND(OR(W22=2,W22=3),X22<>"",Y22<>"",X22>=I22,Y22<=J22,Y22>X22),"通过","2/3级时间无效")))))
A23: VQ-001 | B23: 空气炸锅怎样设置烹饪温度和时间？ | C23: zh-CN | D23: Air Fryer | E23: operation | F23: development | G23: airfryer-032-scene-0006 | H23: airfryer-032 | I23: 14.767 | J23: 16.767 | K23: items/airfryer-032-scene-0006/clip.mp4 | L23: items/airfryer-032-scene-0006/thumbnail.jpg | M23: ASR: this. Hey there my name is Kathy from fabulouslyfrugal.com and every Sunday morning I'm sharing VLM: Visual summary: A close-up view of the interior of an appliance showing a spiral heating element on a metal cooking surface. 视觉摘要: 一个电器内部的特写，显示一个螺旋形加热元件位于金属烹饪表面上。 Visible product: Air Fryer Visible components: spiral heating element; metal cooking surface; metal interior walls; ventilation slots; screws Visual uncertainty: The product is labeled as an air fryer, but the visible components do not clearly indicate air frying functionality such as a fan or basket. | N23: 22 | O23: 1 | R23: The visual shows an air fryer's interior with a spiral heating element, but no visible controls, display, or instructions for setting temperature and time. | S23: VLM | T23: low | U23: No evidence of temperature or time setting interface or instructions shown in the scene. | V23: R1 | W23: 1 | Z23: no | AA23: 画面展示打开机体露出加热元件，但未展示控制面板或温度/时间设置。 | AC23: completed | AD23: 2026-07-27T22:17:08+08:00 | AE23: =IF(AC23<>"completed","",IF(W23=O23,"no","yes")) | AF23: =IF(AC23<>"completed","",IF(AND(X23=P23,Y23=Q23),"no","yes")) | AG23: =IF(AC23<>"completed","待复核",IF(OR(W23="",Z23="",AA23="",AD23=""),"缺少必填项",IF(AND(OR(AE23="yes",AF23="yes"),AB23=""),"修正原因缺失",IF(OR(W23=0,W23=1),IF(AND(X23="",Y23=""),"通过","0/1级时间应留空"),IF(AND(OR(W23=2,W23=3),X23<>"",Y23<>"",X23>=I23,Y23<=J23,Y23>X23),"通过","2/3级时间无效")))))
A24: VQ-001 | B24: 空气炸锅怎样设置烹饪温度和时间？ | C24: zh-CN | D24: Air Fryer | E24: operation | F24: development | G24: airfryer-024-scene-0009 | H24: airfryer-024 | I24: 36.536 | J24: 40.974 | K24: items/airfryer-024-scene-0009/clip.mp4 | L24: items/airfryer-024-scene-0009/thumbnail.jpg | M24: ASR: The optional preheat function makes grilling, searing, and broiling easy and fast, with perfect results each and every time. OCR: PERFECT RESULTS Every Time! VLM: Visual summary: A close-up of an air fryer's digital control panel displaying a temperature of 375°F, with text indicating an 'Optional PREHEAT FUNCTION' and 'Patent Pending'. The scene then transitions to show three cooking modes: grilling, searing, and broiling, each with food items inside the air fryer basket. 视觉摘要: 一台空气炸锅的数字控制面板特写，显示温度为375°F，配有“可选预热功能”和“专利待定”字样。随后画面切换，展示三种烹饪模式：烧烤、煎制和烘烤，每个模式下都有食物在炸篮中。 Visible product: Air Fryer Visible components: digital display; temperature reading; control buttons; cooking mode icons; air fryer basket; food items (steaks, scallops, chicken, sweet potatoes) Visible states: temperature set to 375°F; preheat function indicated; food being cooked in different modes | N24: 23 | O24: 2 | P24: 36.536 | Q24: 40.974 | R24: The scene shows the air fryer's digital display set to 375°F and demonstrates cooking modes (grilling, searing, broiling) with food items, indicating how temperature and mode selection are used, though it does not explicitly show time setting. | S24: VLM|ASR|OCR | T24: low | U24: No explicit mention or visual of time setting functionality. | V24: R1 | W24: 2 | X24: 36.536 | Y24: 40.974 | Z24: no | AA24: 数字屏显示375°F及PREHEAT FUNCTION，展示了温度设置，但未明确展示时间设置。 | AC24: completed | AD24: 2026-07-27T22:17:08+08:00 | AE24: =IF(AC24<>"completed","",IF(W24=O24,"no","yes")) | AF24: =IF(AC24<>"completed","",IF(AND(X24=P24,Y24=Q24),"no","yes")) | AG24: =IF(AC24<>"completed","待复核",IF(OR(W24="",Z24="",AA24="",AD24=""),"缺少必填项",IF(AND(OR(AE24="yes",AF24="yes"),AB24=""),"修正原因缺失",IF(OR(W24=0,W24=1),IF(AND(X24="",Y24=""),"通过","0/1级时间应留空"),IF(AND(OR(W24=2,W24=3),X24<>"",Y24<>"",X24>=I24,Y24<=J24,Y24>X24),"通过","2/3级时间无效")))))
A25: VQ-001 | B25: 空气炸锅怎样设置烹饪温度和时间？ | C25: zh-CN | D25: Air Fryer | E25: operation | F25: development | G25: pressure-006-scene-0010 | H25: pressure-006 | I25: 29.458 | J25: 34.083 | K25: items/pressure-006-scene-0010/clip.mp4 | L25: items/pressure-006-scene-0010/thumbnail.jpg | M25: ASR: • 360-degree hot air baking, wrapping heating, original flavor, 1500W high power, rapid heating OCR: 1500 W high-power rapid heating VLM: Visual summary: Food items are cooking inside an air fryer, with text overlays indicating '360 air cooking' and '1500 W high-power rapid heating'. 视觉摘要: 食物在空气炸锅内烹饪，画面中有文字叠加显示“360空气烹饪”和“1500W高功率快速加热”。 Visible product: Air Fryer Visible components: food items; air fryer basket; text overlay Visible states: food is cooking; air fryer is operating Visual uncertainty: The specific model or brand of the air fryer is not visible. The exact type of food is not clearly identifiable. | N25: 24 | O25: 1 | R25: The scene shows an air fryer operating with text overlays indicating '360 air cooking' and '1500W high-power rapid heating', but no explicit instruction or setting of temperature or time is shown or mentioned. | S25: VLM|ASR|OCR | T25: low | U25: No visible or spoken evidence of temperature or time settings being adjusted or displayed. | V25: R1 | W25: 1 | Z25: no | AA25: 画面展示食物在空炸锅内烹饪，叠加“360 air cooking”等文字，但未展示具体温度/时间设置。 | AC25: completed | AD25: 2026-07-27T22:17:08+08:00 | AE25: =IF(AC25<>"completed","",IF(W25=O25,"no","yes")) | AF25: =IF(AC25<>"completed","",IF(AND(X25=P25,Y25=Q25),"no","yes")) | AG25: =IF(AC25<>"completed","待复核",IF(OR(W25="",Z25="",AA25="",AD25=""),"缺少必填项",IF(AND(OR(AE25="yes",AF25="yes"),AB25=""),"修正原因缺失",IF(OR(W25=0,W25=1),IF(AND(X25="",Y25=""),"通过","0/1级时间应留空"),IF(AND(OR(W25=2,W25=3),X25<>"",Y25<>"",X25>=I25,Y25<=J25,Y25>X25),"通过","2/3级时间无效")))))
A26: VQ-001 | B26: 空气炸锅怎样设置烹饪温度和时间？ | C26: zh-CN | D26: Air Fryer | E26: operation | F26: development | G26: airfryer-002-scene-0010 | H26: airfryer-002 | I26: 257.424 | J26: 283.851 | K26: items/airfryer-002-scene-0010/clip.mp4 | L26: items/airfryer-002-scene-0010/thumbnail.jpg | M26: ASR: spray we're now going to place our cookies in the basket seam side down we're going to cook for seven minutes so it's been about seven minutes and i believe our cookies are about done So as you can see, the puff pastry is golden brown with a cookie in the middle. OCR: Lirary Riden Puff Pastry SHEETS OREO Chef Library Kitchen wnen VLM: Visual summary: A man in a blue apron stands behind a kitchen counter with an air fryer, ingredients, and kitchen tools. He gestures and interacts with the air fryer basket. 视觉摘要: 一名穿着蓝色围裙的男子站在厨房操作台前，台面上有空气炸锅、食材和厨具。他做出手势并与空气炸锅的篮子互动。 Visible product: Air Fryer Visible components: air fryer; air fryer basket; puff pastry sheets; OREO cookies; powdered sugar container; spray bottle; silicone mat; white plate; red placemat; chef apron; glasses; watch Visible actions: gesturing with hand; holding air fryer basket; pointing at air fryer basket; placing hand on counter Visible states: man smiling; air fryer basket being held; ingredients arranged on counter | N26: 25 | O26: 1 | R26: ASR mentions cooking for seven minutes, but does not specify how to set temperature or time on the air fryer; VLM shows interaction with the air fryer basket but no visible setting of temperature or time. | S26: ASR|VLM | T26: low | U26: No visible or spoken evidence of temperature or time setting on the air fryer control panel. | V26: R1 | W26: 1 | Z26: no | AA26: ASR提到烹饪7分钟，但未在画面中展示温度/时间设置操作。 | AC26: completed | AD26: 2026-07-27T22:20:03+08:00 | AE26: =IF(AC26<>"completed","",IF(W26=O26,"no","yes")) | AF26: =IF(AC26<>"completed","",IF(AND(X26=P26,Y26=Q26),"no","yes")) | AG26: =IF(AC26<>"completed","待复核",IF(OR(W26="",Z26="",AA26="",AD26=""),"缺少必填项",IF(AND(OR(AE26="yes",AF26="yes"),AB26=""),"修正原因缺失",IF(OR(W26=0,W26=1),IF(AND(X26="",Y26=""),"通过","0/1级时间应留空"),IF(AND(OR(W26=2,W26=3),X26<>"",Y26<>"",X26>=I26,Y26<=J26,Y26>X26),"通过","2/3级时间无效")))))
A27: VQ-001 | B27: 空气炸锅怎样设置烹饪温度和时间？ | C27: zh-CN | D27: Air Fryer | E27: operation | F27: development | G27: airfryer-006-scene-0005 | H27: airfryer-006 | I27: 16.817 | J27: 19.92 | K27: items/airfryer-006-scene-0005/clip.mp4 | L27: items/airfryer-006-scene-0005/thumbnail.jpg | M27: ASR: Your air fryer, 350, four minutes for the first side. Here it goes. VLM: Visual summary: A woman in a pink shirt is standing in a kitchen next to a white air fryer, gesturing with her hand while speaking. 视觉摘要: 一位穿着粉色衬衫的女士站在厨房里，旁边是一台白色空气炸锅，她正用手势配合说话。 Visible product: Air Fryer Visible components: white air fryer; digital display; control buttons; brand name 'COSORI'; temperature setting '350°'; shelf with plates; plant Visible actions: woman gesturing with her right hand; woman speaking | N27: 26 | O27: 3 | P27: 16.817 | Q27: 19.92 | R27: ASR states 'Your air fryer, 350, four minutes for the first side', and VLM shows the air fryer with visible temperature setting '350°', directly indicating how to set temperature and time. | S27: ASR|VLM | T27: low | U27: No ambiguity in the ASR text or VLM visual evidence regarding the temperature and time setting. | V27: R1 | W27: 3 | X27: 16.817 | Y27: 19.92 | Z27: no | AA27: 画面中白色空气炸锅显示屏显示350°F，并叠加文字“AIR FRY AT 350°F FOR 4 MINUTES”，直接给出温度与时间设置。 | AC27: completed | AD27: 2026-07-27T22:20:03+08:00 | AE27: =IF(AC27<>"completed","",IF(W27=O27,"no","yes")) | AF27: =IF(AC27<>"completed","",IF(AND(X27=P27,Y27=Q27),"no","yes")) | AG27: =IF(AC27<>"completed","待复核",IF(OR(W27="",Z27="",AA27="",AD27=""),"缺少必填项",IF(AND(OR(AE27="yes",AF27="yes"),AB27=""),"修正原因缺失",IF(OR(W27=0,W27=1),IF(AND(X27="",Y27=""),"通过","0/1级时间应留空"),IF(AND(OR(W27=2,W27=3),X27<>"",Y27<>"",X27>=I27,Y27<=J27,Y27>X27),"通过","2/3级时间无效")))))
A28: VQ-001 | B28: 空气炸锅怎样设置烹饪温度和时间？ | C28: zh-CN | D28: Air Fryer | E28: operation | F28: development | G28: airfryer-017-scene-0112 | H28: airfryer-017 | I28: 1506.839 | J28: 1523.722 | K28: items/airfryer-017-scene-0112/clip.mp4 | L28: items/airfryer-017-scene-0112/thumbnail.jpg | M28: ASR: so there we go we're back in action i'll let you know if it breaks again and if i fix it again OCR: 2 VLM: Visual summary: A person is interacting with a silver air fryer on a kitchen counter, next to a toaster and red containers. 视觉摘要: 一个人在厨房台面上与一台银色空气炸锅互动，旁边有一个烤面包机和红色容器。 Visible product: Air Fryer Visible components: silver air fryer; toaster; red containers; black tiled backsplash; white cabinets; digital display; control panel Visible actions: person pressing a button on the air fryer; person bending over the counter Visible states: air fryer display shows 'OFF' Visual uncertainty: The person's face and full body are not visible. The contents inside the air fryer are not clearly identifiable. | N28: 27 | O28: 1 | R28: The scene shows a person interacting with an air fryer, but no temperature or time settings are visible or mentioned; the display shows 'OFF' and no actionable settings are demonstrated. | S28: VLM | T28: low | U28: No evidence of temperature or time setting actions or values is present. | V28: R1 | W28: 1 | Z28: no | AA28: 画面显示空气炸锅显示屏为OFF，未展示温度/时间设置。 | AC28: completed | AD28: 2026-07-27T22:20:03+08:00 | AE28: =IF(AC28<>"completed","",IF(W28=O28,"no","yes")) | AF28: =IF(AC28<>"completed","",IF(AND(X28=P28,Y28=Q28),"no","yes")) | AG28: =IF(AC28<>"completed","待复核",IF(OR(W28="",Z28="",AA28="",AD28=""),"缺少必填项",IF(AND(OR(AE28="yes",AF28="yes"),AB28=""),"修正原因缺失",IF(OR(W28=0,W28=1),IF(AND(X28="",Y28=""),"通过","0/1级时间应留空"),IF(AND(OR(W28=2,W28=3),X28<>"",Y28<>"",X28>=I28,Y28<=J28,Y28>X28),"通过","2/3级时间无效")))))
A29: VQ-001 | B29: 空气炸锅怎样设置烹饪温度和时间？ | C29: zh-CN | D29: Air Fryer | E29: operation | F29: development | G29: airfryer-024-scene-0021 | H29: airfryer-024 | I29: 93.56 | J29: 99.8 | K29: items/airfryer-024-scene-0021/clip.mp4 | L29: items/airfryer-024-scene-0021/thumbnail.jpg | M29: ASR: Simply use the digital touchscreen and cook from 100 degrees to 400 degrees in 5 degree increments. The Brio's 3 quart capacity can make meals for one or the whole family. OCR: nuwave Temperature Range 360F 100°- 400° 360°F 360'F In 5º 390F Increments 15-22mnins 3907 6-10mins 5-10mns VLM: Visual summary: A hand is interacting with the digital touchscreen of a NuWave air fryer, adjusting the temperature setting. 视觉摘要: 一只手正在操作一台NuWave空气炸锅的数字触摸屏，调整温度设置。 Visible product: NuWave Visible components: digital touchscreen; temperature display; touch buttons; temperature icons; product branding Visible actions: hand touching screen Visible states: temperature displayed as 105°F; temperature displayed as 215°F | N29: 28 | O29: 3 | P29: 93.56 | Q29: 99.8 | R29: The ASR explicitly states how to set temperature (100-400°F in 5° increments) and mentions time ranges (15-22 mins, 6-10 mins, 5-10 mins) for specific temperatures. The VLM shows a hand adjusting temperature on the touchscreen, and OCR confirms the temperature range and increments. All evidence directly answers the question. | S29: VLM|ASR|OCR | T29: low | U29: All evidence is complete and directly addresses the question without ambiguity. | V29: R1 | W29: 2 | X29: 93.56 | Y29: 99.8 | Z29: no | AA29: 六帧清晰展示手指操作Nuwave空气炸锅数字触摸屏，屏幕温度在100°F→125°F→155°F→215°F之间变化，叠加'Temperature Range 100°-400° In 5° Increments'与'DIGITAL Touch Screen'字幕；但仅演示温度调节流程，未演示时间/定时设置步骤。 | AB29: 第三轮双复核一致修正：R1=3→独立=2：query问'温度与时间'两步，画面只回答温度设置未演示时间设置，无法构成完整回答；时间区间一致。 | AC29: completed | AD29: 2026-07-28T20:35:21+08:00 | AE29: =IF(AC29<>"completed","",IF(W29=O29,"no","yes")) | AF29: =IF(AC29<>"completed","",IF(AND(X29=P29,Y29=Q29),"no","yes")) | AG29: =IF(AC29<>"completed","待复核",IF(OR(W29="",Z29="",AA29="",AD29=""),"缺少必填项",IF(AND(OR(AE29="yes",AF29="yes"),AB29=""),"修正原因缺失",IF(OR(W29=0,W29=1),IF(AND(X29="",Y29=""),"通过","0/1级时间应留空"),IF(AND(OR(W29=2,W29=3),X29<>"",Y29<>"",X29>=I29,Y29<=J29,Y29>X29),"通过","2/3级时间无效")))))
A30: VQ-001 | B30: 空气炸锅怎样设置烹饪温度和时间？ | C30: zh-CN | D30: Air Fryer | E30: operation | F30: development | G30: airfryer-029-scene-0045 | H30: airfryer-029 | I30: 272.4 | J30: 276.6 | K30: items/airfryer-029-scene-0045/clip.mp4 | L30: items/airfryer-029-scene-0045/thumbnail.jpg | M30: ASR: temperature whereas meats usually I prefer to cook at high temperature so I'm going to preheat at 200 degree centigrade for around 5 minutes. The built in timer of the OCR: Philips SUPER CHEF VLM: Visual summary: A person is operating a black Philips air fryer, adjusting its control dial. 视觉摘要: 一个人正在操作一台黑色的飞利浦空气炸锅，调整其控制旋钮。 Visible product: Philips Visible components: air fryer; control dial; temperature indicator; recipe guide label; brand logo Visible actions: hand adjusting control dial; hand on top lid Visible states: air fryer in use; control dial set to a specific setting Visual uncertainty: The exact setting on the control dial is not clearly readable, and the specific food being cooked is not visible. | N30: 29 | O30: 2 | P30: 272.4 | Q30: 276.6 | R30: ASR mentions setting temperature to 200 degrees Celsius and preheating for 5 minutes, which directly relates to the question. VLM shows hand adjusting the control dial, indicating temperature/time setting action, though exact values are not visible. | S30: ASR|VLM | T30: medium | U30: The exact temperature and time values are not fully visible in the VLM, and the ASR is partially cut off, leaving ambiguity about whether the full setting process is covered. | V30: R1 | W30: 3 | X30: 272.4 | Y30: 276.6 | Z30: no | AA30: 画面中手指正在调节飞利浦空气炸锅的温度/时间旋钮，ASR明确说明预热200°C约5分钟，直接展示设置过程。 | AB30: AI=2→R1=3 | AC30: completed | AD30: 2026-07-27T22:23:08+08:00 | AE30: =IF(AC30<>"completed","",IF(W30=O30,"no","yes")) | AF30: =IF(AC30<>"completed","",IF(AND(X30=P30,Y30=Q30),"no","yes")) | AG30: =IF(AC30<>"completed","待复核",IF(OR(W30="",Z30="",AA30="",AD30=""),"缺少必填项",IF(AND(OR(AE30="yes",AF30="yes"),AB30=""),"修正原因缺失",IF(OR(W30=0,W30=1),IF(AND(X30="",Y30=""),"通过","0/1级时间应留空"),IF(AND(OR(W30=2,W30=3),X30<>"",Y30<>"",X30>=I30,Y30<=J30,Y30>X30),"通过","2/3级时间无效")))))
